<?xml version="1.0" ?>
<!-- =================================================================================== -->
<!-- |    This document was autogenerated by xacro from irb2400_workspace.xacro        | -->
<!-- |    EDITING THIS FILE BY HAND IS NOT RECOMMENDED                                 | -->
<!-- =================================================================================== -->
<robot name="irb2400_workspace" xmlns:xacro="http://ros.org/wiki/xacro">
  <!-- Conversion were obtained from http://www.e-paint.co.uk/Lab_values.asp
       unless otherwise stated. -->
  <!--
  <xacro:property name="keyence_tcp_x" value="0.0006"/>
  <xacro:property name="keyence_tcp_y" value="0.2863"/>
  <xacro:property name="keyence_tcp_z" value="0.0968"/>
  -->
  <!-- TBD -->
  <!--96"  vertical-->
  <!-- middle of width -->
  <link name="world_frame"/>
  <!-- link list -->
  <link name="base_link">
    <visual>
      <origin rpy="0 0 0" xyz="0 0 0"/>
      <geometry>
        <mesh filename="package://abb_irb2400_support/meshes/irb2400/visual/base_link.dae"/>
      </geometry>
      <material name="">
        <color rgba="0.7372549 0.3490196 0.1607843 1"/>
      </material>
    </visual>
    <collision>
      <geometry>
        <mesh filename="package://abb_irb2400_support/meshes/irb2400/collision/base_link.stl"/>
      </geometry>
      <material name="">
        <color rgba="1 1 0 1"/>
      </material>
    </collision>
  </link>
  <link name="link_1">
    <visual>
      <origin rpy="0 0 0" xyz="0 0 0"/>
      <geometry>
        <mesh filename="package://abb_irb2400_support/meshes/irb2400/visual/link_1.dae"/>
      </geometry>
      <material name="">
        <color rgba="0.7372549 0.3490196 0.1607843 1"/>
      </material>
    </visual>
    <collision>
      <origin rpy="0 0 0" xyz="0 0 0"/>
      <geometry>
        <mesh filename="package://abb_irb2400_support/meshes/irb2400/collision/link_1.stl"/>
      </geometry>
      <material name="">
        <color rgba="1 1 0 1"/>
      </material>
    </collision>
  </link>
  <link name="link_2">
    <visual>
      <origin rpy="0 0 0" xyz="0 0 0"/>
      <geometry>
        <mesh filename="package://abb_irb2400_support/meshes/irb2400/visual/link_2.dae"/>
      </geometry>
      <material name="">
        <color rgba="0.7372549 0.3490196 0.1607843 1"/>
      </material>
    </visual>
    <collision>
      <origin rpy="0 0 0" xyz="0 0 0"/>
      <geometry>
        <mesh filename="package://abb_irb2400_support/meshes/irb2400/collision/link_2_whole.stl"/>
      </geometry>
      <material name="">
        <color rgba="1 1 0 1"/>
      </material>
    </collision>
  </link>
  <link name="link_3">
    <visual>
      <origin rpy="0 0 0" xyz="0 0 0"/>
      <geometry>
        <mesh filename="package://abb_irb2400_support/meshes/irb2400/visual/link_3.dae"/>
      </geometry>
      <material name="">
        <color rgba="0.7372549 0.3490196 0.1607843 1"/>
      </material>
    </visual>
    <collision>
      <origin rpy="0 0 0" xyz="0 0 0"/>
      <geometry>
        <mesh filename="package://abb_irb2400_support/meshes/irb2400/collision/link_3.stl"/>
      </geometry>
      <material name="">
        <color rgba="1 1 0 1"/>
      </material>
    </collision>
  </link>
  <link name="link_4">
    <visual>
      <origin rpy="0 0 0" xyz="0 0 0"/>
      <geometry>
        <mesh filename="package://abb_irb2400_support/meshes/irb2400/visual/link_4.dae"/>
      </geometry>
      <material name="">
        <color rgba="0.7372549 0.3490196 0.1607843 1"/>
      </material>
    </visual>
    <collision>
      <origin rpy="0 0 0" xyz="0 0 0"/>
      <geometry>
        <mesh filename="package://abb_irb2400_support/meshes/irb2400/collision/link_4.stl"/>
      </geometry>
      <material name="">
        <color rgba="1 1 0 1"/>
      </material>
    </collision>
  </link>
  <link name="link_5">
    <visual>
      <origin rpy="0 0 0" xyz="0 0 0"/>
      <geometry>
        <mesh filename="package://abb_irb2400_support/meshes/irb2400/visual/link_5.dae"/>
      </geometry>
      <material name="">
        <color rgba="0.7372549 0.3490196 0.1607843 1"/>
      </material>
    </visual>
    <collision>
      <origin rpy="0 0 0" xyz="0 0 0"/>
      <geometry>
        <mesh filename="package://abb_irb2400_support/meshes/irb2400/collision/link_5.stl"/>
      </geometry>
      <material name="">
        <color rgba="1 1 0 1"/>
      </material>
    </collision>
  </link>
  <link name="link_6">
    <visual>
      <origin rpy="0 0 0" xyz="0 0 0"/>
      <geometry>
        <mesh filename="package://abb_irb2400_support/meshes/irb2400/visual/link_6.dae"/>
      </geometry>
      <material name="">
        <color rgba="0.1882353 0.1960784 0.2039216 1"/>
      </material>
    </visual>
    <collision>
      <origin rpy="0 0 0" xyz="0 0 0"/>
      <geometry>
        <mesh filename="package://abb_irb2400_support/meshes/irb2400/collision/link_6.stl"/>
      </geometry>
      <material name="">
        <color rgba="1 1 0 1"/>
      </material>
    </collision>
  </link>
  <link name="tool0"/>
  <!-- end of link list -->
  <!-- joint list -->
  <joint name="joint_1" type="revolute">
    <origin rpy="0 0 0" xyz="0 0 0"/>
    <parent link="base_link"/>
    <child link="link_1"/>
    <axis xyz="0 0 1"/>
    <limit effort="0" lower="-3.1416" upper="3.1416" velocity="2.618"/>
  </joint>
  <joint name="joint_2" type="revolute">
    <origin rpy="0 0 0" xyz="0.1 0 0.615"/>
    <parent link="link_1"/>
    <child link="link_2"/>
    <axis xyz="0 1 0"/>
    <limit effort="0" lower="-1.7453" upper="1.9199" velocity="2.618"/>
  </joint>
  <joint name="joint_3" type="revolute">
    <origin rpy="0 0 0" xyz="0 0 0.705"/>
    <parent link="link_2"/>
    <child link="link_3"/>
    <axis xyz="0 1 0"/>
    <limit effort="0" lower="-1.0472" upper="1.1345" velocity="2.618"/>
  </joint>
  <joint name="joint_4" type="revolute">
    <origin rpy="0 0 0" xyz="0.258 0 0.135"/>
    <parent link="link_3"/>
    <child link="link_4"/>
    <axis xyz="1 0 0"/>
    <limit effort="0" lower="-3.49" upper="3.49" velocity="6.2832"/>
  </joint>
  <joint name="joint_5" type="revolute">
    <origin rpy="0 0 0" xyz="0.497 0 0"/>
    <parent link="link_4"/>
    <child link="link_5"/>
    <axis xyz="0 1 0"/>
    <limit effort="0" lower="-2.0944" upper="2.0944" velocity="6.2832"/>
  </joint>
  <joint name="joint_6" type="revolute">
    <origin rpy="0 0 0" xyz="0.085 0 0"/>
    <parent link="link_5"/>
    <child link="link_6"/>
    <axis xyz="1 0 0"/>
    <limit effort="0" lower="-6.9813" upper="6.9813" velocity="7.854"/>
  </joint>
  <joint name="joint_6-tool0" type="fixed">
    <parent link="link_6"/>
    <child link="tool0"/>
    <origin rpy="0 1.57079632679 0" xyz="0 0 0"/>
  </joint>
  <!-- end of joint list -->
  <!-- ROS base_link to ABB World Coordinates transform -->
  <link name="base"/>
  <joint name="base_link-base" type="fixed">
    <origin rpy="0 0 0" xyz="0 0 0"/>
    <parent link="base_link"/>
    <child link="base"/>
  </joint>
  <!-- eff_frame is Base Link -->
  <link name="eff_frame"/>
  <link name="adapter_tube">
    <!--
      <visual>
        <geometry>
          <mesh filename="package://blending_end_effector/meshes/visual/Adapter_Tube.STL"/>
        </geometry>
        <material name="grey">
          <color rgba="0.5 0.5 0.5 1.0"/>
        </material>
      </visual>
      <collision>
        <geometry>
          <mesh filename="package://blending_end_effector/meshes/collision/adapter_tube_convex_hull.STL"/>
        </geometry>
      </collision>
      -->
  </link>
  <joint name="eff_frame_to_adapter_tube" type="fixed">
    <parent link="eff_frame"/>
    <child link="adapter_tube"/>
    <origin rpy="0 0 0" xyz="0 0 0"/>
  </joint>
  <link name="bracket">
    <!--
      <visual>
        <geometry>
          <mesh filename="package://blending_end_effector/meshes/visual/Tool_Mounting_Plate.STL"/>
        </geometry>
        <material name="grey">
          <color rgba="0.5 0.5 0.5 1.0"/>
        </material>
      </visual>
      <collision>
        <geometry>
          <mesh filename="package://blending_end_effector/meshes/collision/EE_and_Tool_Changer_convex_hull.STL"/>
        </geometry>
      </collision>
      -->
  </link>
  <joint name="adapter_tube_to_bracket" type="fixed">
    <parent link="adapter_tube"/>
    <child link="bracket"/>
    <origin rpy="0 0 0" xyz="0 0 0"/>
  </joint>
  <link name="blending_tool">
    <!--
        <visual>
            <geometry>
                <mesh filename="package://blending_end_effector/meshes/visual/Blending_Tool.STL"/>
            </geometry>
            <material name="red">
                <color rgba="1 0 0 1"/>
            </material>
        </visual>
	-->
    <visual>
      <geometry>
        <!--<mesh filename="package://blending_end_effector/meshes/visual/Blending_Tool.STL"/>-->
        <mesh filename="package://blending_end_effector/meshes/visual/Mesje.STL"/>
      </geometry>
      <material name="red">
        <color rgba="1 0 0 1"/>
      </material>
    </visual>
  </link>
  <joint name="bracket_to_blending_tool" type="fixed">
    <parent link="bracket"/>
    <child link="blending_tool"/>
    <origin rpy="-1.57079632679 -1.57079632679 0" xyz="-0.01 -0.01 -0.01"/>
    <!--<origin xyz="0.01 0.01 -0.01" rpy="${half_pi} -${half_pi} 0"/>-->
  </joint>
  <link name="ensenso">
    <!--
        <visual>
            <geometry>
                <mesh filename="package://blending_end_effector/meshes/visual/Ensenso.STL"/>
            </geometry>
            <material name="blue">
                <color rgba="0 0 1 1"/>
            </material>
        </visual>
	-->
  </link>
  <joint name="bracket_to_ensenso" type="fixed">
    <parent link="bracket"/>
    <child link="ensenso"/>
  </joint>
  <link name="keyence">
    <!--
        <visual>
            <geometry>
                <mesh filename="package://blending_end_effector/meshes/visual/Laser_Sensor.STL"/>
            </geometry>
            <material name="yellow">
                <color rgba="1 1 0 1"/>
            </material>
        </visual>
	-->
  </link>
  <joint name="bracket_to_keyence" type="fixed">
    <parent link="bracket"/>
    <child link="keyence"/>
  </joint>
  <!-- Frames for the motorized spindle on the end-->
  <link name="chuck_tip_frame"/>
  <!--The tip of the chuck-->
  <link name="tcp_frame"/>
  <!--The actual 'useful' work frame-->
  <joint name="bracket_to_chuck" type="fixed">
    <parent link="bracket"/>
    <child link="chuck_tip_frame"/>
    <origin rpy="0 -1.57079632679 0" xyz="-0.2507 -0.0035 0.1228"/>
  </joint>
  <joint name="chuck_to_blend_tcp_frame" type="fixed">
    <parent link="chuck_tip_frame"/>
    <child link="tcp_frame"/>
    <origin rpy="0 0 0" xyz="0 0 0.04"/>
  </joint>
  <!--Frames for the keyence profilometer-->
  <link name="keyence_sensor_optical_frame"/>
  <!--The emitter lens-->
  <!--<link name="${prefix}keyence_tcp_frame"/>-->
  <!--The nominal scan location (8cm forward of emitter)-->
  <link name="keyence_tcp_frame">
    <visual>
      <geometry>
        <box size="0.01 0.01 0.01"/>
      </geometry>
    </visual>
  </link>
  <joint name="bracket_to_keyence_sof" type="fixed">
    <parent link="bracket"/>
    <child link="keyence_sensor_optical_frame"/>
    <!--<origin xyz="${keyence_tcp_x} ${keyence_tcp_y} ${keyence_tcp_z}" rpy="-${half_pi} ${half_pi} 0"/>-->
    <origin rpy="-1.57079632679 1.57079632679 0" xyz="0.0 0.0 0.2"/>
    <!--<origin xyz="0.2 0.005 0.03" rpy="0 0 0"/>-->
  </joint>
  <joint name="bracket_to_keyence_tcp_f" type="fixed">
    <parent link="bracket"/>
    <child link="keyence_tcp_frame"/>
    <!--<origin xyz="${keyence_tcp_x} ${keyence_tcp_y} ${keyence_tcp_z}" rpy="-${half_pi} ${half_pi} 0"/>-->
    <origin rpy="-1.57079632679 1.57079632679 0" xyz="0.0 0.0 0.2"/>
    <!--<origin xyz="0.2 0.005 0.03" rpy="0 0 0"/>-->
  </joint>
  <!--Frames related to the motion of the camera-->
  <link name="ensenso_sensor_optical_frame"/>
  <link name="kinect2_move_frame"/>
  <joint name="bracket_to_ensenso_sof" type="fixed">
    <parent link="bracket"/>
    <child link="ensenso_sensor_optical_frame"/>
    <origin rpy="0 0 0" xyz="0 0.0909 0.1255"/>
  </joint>
  <joint name="ensenso_move_frame_join" type="fixed">
    <parent link="ensenso_sensor_optical_frame"/>
    <child link="kinect2_move_frame"/>
    <origin rpy="0 -1.57079632679 0"/>
  </joint>
  <link name="demo_cell_base_link"/>
  <link name="demo_cell_corner"/>
  <link name="demo_cell_back_wall">
    <collision>
      <geometry>
        <box size="0.05 1.524 2.4384"/>
      </geometry>
    </collision>
  </link>
  <link name="demo_cell_right_wall">
    <collision>
      <geometry>
        <box size="1.8288 0.05 2.4384"/>
      </geometry>
    </collision>
  </link>
  <link name="demo_cell_left_wall">
    <collision>
      <geometry>
        <box size="1.8288 0.05 2.4384"/>
      </geometry>
    </collision>
  </link>
  <!-- light curtains -->
  <link name="demo_cell_front_wall">
    <collision>
      <geometry>
        <box size="0.05 1.524 2.4384"/>
      </geometry>
    </collision>
  </link>
  <link name="demo_cell_roof">
    <collision>
      <geometry>
        <box size="1.8288 1.524 0.05"/>
      </geometry>
    </collision>
  </link>
  <link name="demo_cell_floor">
    <collision>
      <geometry>
        <box size="1.8288 1.524 0.05"/>
      </geometry>
    </collision>
  </link>
  <joint name="cell_baselink_to_corner" type="fixed">
    <parent link="demo_cell_base_link"/>
    <child link="demo_cell_corner"/>
    <origin xyz="-0.45 -0.762 0"/>
  </joint>
  <joint name="cell_corner_to_back" type="fixed">
    <parent link="demo_cell_corner"/>
    <child link="demo_cell_back_wall"/>
    <origin xyz="-0.025 0.762 1.2192"/>
  </joint>
  <joint name="cell_corner_to_left" type="fixed">
    <parent link="demo_cell_corner"/>
    <child link="demo_cell_left_wall"/>
    <origin xyz="0.9144 -0.025 1.2192"/>
  </joint>
  <joint name="cell_corner_to_front" type="fixed">
    <parent link="demo_cell_corner"/>
    <child link="demo_cell_front_wall"/>
    <origin xyz="1.8538 0.762 1.2192"/>
  </joint>
  <joint name="cell_corner_to_right" type="fixed">
    <parent link="demo_cell_corner"/>
    <child link="demo_cell_right_wall"/>
    <origin xyz="0.9144 1.549 1.2192"/>
  </joint>
  <joint name="cell_corner_to_roof" type="fixed">
    <parent link="demo_cell_corner"/>
    <child link="demo_cell_roof"/>
    <origin xyz="0.9144 0.762 2.4634"/>
  </joint>
  <joint name="cell_corner_to_floor" type="fixed">
    <parent link="demo_cell_corner"/>
    <child link="demo_cell_floor"/>
    <origin xyz="0.9144 0.762 -0.025"/>
  </joint>
  <!-- Attach the end effector to the end of the robot arm (tool0) -->
  <joint name="link_t_to_eff" type="fixed">
    <parent link="tool0"/>
    <child link="eff_frame"/>
    <origin rpy="0 0 1.57079632679" xyz="0 0 0"/>
  </joint>
  <!-- start of arm-workcell joint definitions -->
  <joint name="world_to_base" type="fixed">
    <parent link="world_frame"/>
    <child link="base_link"/>
    <origin rpy="0 0 0" xyz="0 0 0"/>
  </joint>
  <joint name="world_to_demo_cell" type="fixed">
    <parent link="world_frame"/>
    <child link="demo_cell_base_link"/>
    <origin rpy="0 0 0" xyz="0 0 0"/>
  </joint>
</robot>
