<?xml version="1.0" ?>
<!-- =================================================================================== -->
<!-- |    This document was autogenerated by xacro from gp25.xacro                     | -->
<!-- |    EDITING THIS FILE BY HAND IS NOT RECOMMENDED                                 | -->
<!-- =================================================================================== -->
<robot name="abb_irb2400" xmlns:xacro="http://ros.org/wiki/xacro">
  <!-- link list -->
  <link name="base_link">
    <visual>
      <geometry>
        <mesh filename="package://yaskawa_gp25_support/meshes/gp25/visual/base_axis.dae"/>
      </geometry>
      <material name="blue">
        <color rgba="0 0 1 1"/>
      </material>
    </visual>
    <collision>
      <geometry>
        <mesh filename="package://yaskawa_gp25_support/meshes/gp25/collision/base_axis.stl"/>
      </geometry>
      <material name="yellow">
        <color rgba="0 1 1 1"/>
      </material>
    </collision>
  </link>
  <link name="vendor_base_link"/>
  <link name="link_1">
    <visual>
      <geometry>
        <mesh filename="package://yaskawa_gp25_support/meshes/gp25/visual/s_axis.dae"/>
      </geometry>
      <material name="silver">
        <color rgba="0.8 0.8 0.8 1"/>
      </material>
    </visual>
    <collision>
      <geometry>
        <mesh filename="package://yaskawa_gp25_support/meshes/gp25/collision/s_axis.stl"/>
      </geometry>
      <material name="yellow"/>
    </collision>
  </link>
  <link name="link_2">
    <visual>
      <geometry>
        <mesh filename="package://yaskawa_gp25_support/meshes/gp25/visual/l_axis.dae"/>
      </geometry>
      <material name="blue"/>
    </visual>
    <collision>
      <geometry>
        <mesh filename="package://yaskawa_gp25_support/meshes/gp25/collision/l_axis.stl"/>
      </geometry>
      <material name="yellow"/>
    </collision>
  </link>
  <link name="link_3">
    <visual>
      <geometry>
        <mesh filename="package://yaskawa_gp25_support/meshes/gp25/visual/u_axis.dae"/>
      </geometry>
      <material name="silver"/>
    </visual>
    <collision>
      <geometry>
        <mesh filename="package://yaskawa_gp25_support/meshes/gp25/collision/u_axis.stl"/>
      </geometry>
      <material name="yellow"/>
    </collision>
  </link>
  <link name="link_4">
    <visual>
      <geometry>
        <mesh filename="package://yaskawa_gp25_support/meshes/gp25/visual/r_axis.dae"/>
      </geometry>
      <material name="blue"/>
    </visual>
    <collision>
      <geometry>
        <mesh filename="package://yaskawa_gp25_support/meshes/gp25/collision/r_axis.stl"/>
      </geometry>
      <material name="yellow"/>
    </collision>
  </link>
  <link name="link_5">
    <visual>
      <geometry>
        <mesh filename="package://yaskawa_gp25_support/meshes/gp25/visual/b_axis.dae"/>
      </geometry>
      <material name="silver"/>
    </visual>
    <collision>
      <geometry>
        <mesh filename="package://yaskawa_gp25_support/meshes/gp25/collision/b_axis.stl"/>
      </geometry>
      <material name="yellow"/>
    </collision>
  </link>
  <link name="link_6">
    <visual>
      <geometry>
        <mesh filename="package://yaskawa_gp25_support/meshes/gp25/visual/t_axis.dae"/>
      </geometry>
      <material name="blue"/>
    </visual>
    <collision>
      <geometry>
        <mesh filename="package://yaskawa_gp25_support/meshes/gp25/collision/t_axis.stl"/>
      </geometry>
      <material name="yellow"/>
    </collision>
  </link>
  <link name="tool0"/>
  <!-- end of link list -->
  <!-- joint list -->
  <joint name="base_link-base" type="fixed">
    <parent link="base_link"/>
    <child link="vendor_base_link"/>
    <origin xyz="0 0 0.505"/>
  </joint>
  <joint name="joint_1" type="revolute">
    <parent link="base_link"/>
    <child link="link_1"/>
    <origin xyz="0 0 0"/>
    <axis xyz="0 0 1"/>
    <limit effort="100" lower="-3.14159265359" upper="3.14159265359" velocity="3.44"/>
  </joint>
  <joint name="joint_2" type="revolute">
    <parent link="link_1"/>
    <child link="link_2"/>
    <origin xyz="0.150 0 0.505"/>
    <axis xyz="0 1 0"/>
    <limit effort="100" lower="-1.83259571459" upper="2.70526034059" velocity="3.32"/>
  </joint>
  <joint name="joint_3" type="revolute">
    <parent link="link_2"/>
    <child link="link_3"/>
    <origin xyz="0 0 0.760"/>
    <axis xyz="0 -1 0"/>
    <!-- Limited wrt to datasheet to prevent self-collisions -->
    <limit effort="100" lower="-1.50098315672" upper="2.84488668075" velocity="3.67"/>
  </joint>
  <joint name="joint_4" type="revolute">
    <parent link="link_3"/>
    <child link="link_4"/>
    <origin xyz="0 0 0.200"/>
    <axis xyz="-1 0 0"/>
    <limit effort="100" lower="-3.49065850399" upper="3.49065850399" velocity="7.16"/>
  </joint>
  <joint name="joint_5" type="revolute">
    <parent link="link_4"/>
    <child link="link_5"/>
    <origin xyz="0.795 0 0"/>
    <axis xyz="0 -1 0"/>
    <limit effort="100" lower="-2.61799387799" upper="2.61799387799" velocity="7.16"/>
  </joint>
  <joint name="joint_6" type="revolute">
    <parent link="link_5"/>
    <child link="link_6"/>
    <origin xyz="0.100 0 0"/>
    <axis xyz="-1 0 0"/>
    <limit effort="100" lower="-7.94124809657" upper="7.94124809657" velocity="10.82"/>
  </joint>
  <joint name="joint_6-tool0" type="fixed">
    <parent link="link_6"/>
    <child link="tool0"/>
    <origin rpy="0 -1.57079632679 3.14159265359"/>
  </joint>
  <!-- end of joint list -->
</robot>
